Workbook
Name name: 'Reimbursement Request'!#REF!

Sheet Reimbursement Request
A1: S&I Financial Services | E1: S&I Employee Reimbursement Request
E2: General Information
E3: Employee name | O3: Employee ID | T3: Reimbursement rate
E4: Jonathan Saunders | O4: 318977 | T4: 0.7
E5: Address | T5: DeptID for travel
E6: 5506 Cory Lane, Ammon ID 83406 | T6: 3204000
E7: Primary assignment name/address | O7: (If applicable) Secondary assignment name/address
E8: Hillcrest ID Seminary/2801 Owen Street, Ammon ID 83406
A10: Recurring Travel For a trip that happened regularly (daily, weekly, monthly). See the "Completing the Employee Reimbursement Request" help topic.
A11: Address of starting point | M11: Address of destination
A13: Purpose | Q13: Round-trip mi. or km | T13: Round-trip fares or tolls
A15: Month | C15: Check boxes of dates of recurring travel. | S15: Recurring travel totals
C16: 1 | D16: 2 | E16: 3 | F16: 4 | G16: 5 | H16: 6 | I16: 7 | J16: 8 | K16: 9 | L16: 10 | M16: 11 | N16: 12 | O16: 13 | P16: 14 | Q16: 15 | R16: 16 | S16: Days traveled
C17: FALSE | D17: FALSE | E17: FALSE | F17: FALSE | G17: FALSE | H17: FALSE | I17: FALSE | J17: FALSE | K17: FALSE | L17: FALSE | M17: FALSE | N17: FALSE | O17: FALSE | P17: FALSE | Q17: FALSE | R17: FALSE
C18: 17 | D18: 18 | E18: 19 | F18: 20 | G18: 21 | H18: 22 | I18: 23 | J18: 24 | K18: 25 | L18: 26 | M18: 27 | N18: 28 | O18: 29 | P18: 30 | Q18: 31 | S18: =COUNTIF($C17:$W17,TRUE)+COUNTIF($C19:$W19,TRUE)+COUNTIF($C21:$W21,TRUE)+COUNTIF($C23:$W23,TRUE)+COUNTIF($C25:$W25,TRUE)+COUNTIF($C27:$W27,TRUE) -> 0
C19: FALSE | D19: FALSE | E19: FALSE | F19: FALSE | G19: FALSE | H19: FALSE | I19: FALSE | J19: FALSE | K19: FALSE | L19: FALSE | M19: FALSE | N19: FALSE | O19: FALSE | P19: FALSE | Q19: FALSE | R19: FALSE
C20: 1 | D20: 2 | E20: 3 | F20: 4 | G20: 5 | H20: 6 | I20: 7 | J20: 8 | K20: 9 | L20: 10 | M20: 11 | N20: 12 | O20: 13 | P20: 14 | Q20: 15 | R20: 16 | S20: ="Recurring travel reimbursement amount days x (km x rate + fares or tolls) "&IF(S18=0,"",S18&" x ("&IF(Q14=0,"",ROUND(Q14,1)&" x "&IF(T4=0,0,T4))&IF(T14=0,"",IF(Q14=0,""," + ")&T14)&") =") -> Recurring travel reimbursement amount days x (km x rate + fares or tolls)
C21: FALSE | D21: FALSE | E21: FALSE | F21: FALSE | G21: FALSE | H21: FALSE | I21: FALSE | J21: FALSE | K21: FALSE | L21: FALSE | M21: FALSE | N21: FALSE | O21: FALSE | P21: FALSE | Q21: FALSE | R21: FALSE
C22: 17 | D22: 18 | E22: 19 | F22: 20 | G22: 21 | H22: 22 | I22: 23 | J22: 24 | K22: 25 | L22: 26 | M22: 27 | N22: 28 | O22: 29 | P22: 30 | Q22: 31
C23: FALSE | D23: FALSE | E23: FALSE | F23: FALSE | G23: FALSE | H23: FALSE | I23: FALSE | J23: FALSE | K23: FALSE | L23: FALSE | M23: FALSE | N23: FALSE | O23: FALSE | P23: FALSE | Q23: FALSE
C24: 1 | D24: 2 | E24: 3 | F24: 4 | G24: 5 | H24: 6 | I24: 7 | J24: 8 | K24: 9 | L24: 10 | M24: 11 | N24: 12 | O24: 13 | P24: 14 | Q24: 15 | R24: 16 | S24: =ROUND(S18*(ROUND(Q14,1)*T4+T14),2) -> 0
C25: FALSE | D25: FALSE | E25: FALSE | F25: FALSE | G25: FALSE | H25: FALSE | I25: FALSE | J25: FALSE | K25: FALSE | L25: FALSE | M25: FALSE | N25: FALSE | O25: FALSE | P25: FALSE | Q25: FALSE | R25: FALSE
C26: 17 | D26: 18 | E26: 19 | F26: 20 | G26: 21 | H26: 22 | I26: 23 | J26: 24 | K26: 25 | L26: 26 | M26: 27 | N26: 28 | O26: 29 | P26: 30 | Q26: 31
C27: FALSE | D27: FALSE | E27: FALSE | F27: FALSE | G27: FALSE | H27: FALSE | I27: FALSE | J27: FALSE | K27: FALSE | L27: FALSE | M27: FALSE | N27: FALSE | O27: FALSE | P27: FALSE | Q27: FALSE
A29: Varied Travel For one or more individual or infrequent trips. Complete using the guidelines in the "Transportation Documentation Guidelines" help topic.
A30: Date | C30: Starting point (specific location) | H30: Destination (specific location) | M30: Purpose | S30: Mi. or km | T30: Fares or tolls | V30: Amount
V31: =ROUND(S31*$T$4+T31,2) -> 0
V32: =ROUND(S32*$T$4+T32,2) -> 0
V33: =ROUND(S33*$T$4+T33,2) -> 0
V34: =ROUND(S34*$T$4+T34,2) -> 0
V35: =ROUND(S35*$T$4+T35,2) -> 0
V36: =ROUND(S36*$T$4+T36,2) -> 0
V37: =ROUND(S37*$T$4+T37,2) -> 0
V38: =ROUND(S38*$T$4+T38,2) -> 0
V39: =ROUND(S39*$T$4+T39,2) -> 0
V40: =ROUND(S40*$T$4+T40,2) -> 0
V41: =ROUND(S41*$T$4+T41,2) -> 0
V42: =ROUND(S42*$T$4+T42,2) -> 0
... V49: =ROUND(S49*$T$4+T49,2) -> 0
R50: Additional varied travel totals | S50: ='Additional Varied Travel'!E57 -> 0 | T50: ='Additional Varied Travel'!F57 -> 0 | V50: ='Additional Varied Travel'!G57 -> 0
...

Sheet Receipt Detail
A1: Reimbursement Request Receipt Detail
A2: Name
A3: =IF('Reimbursement Request'!N2 <> "",'Reimbursement Request'!N2,"")
A4: Whenever possible, purchase S&I items on a separate transaction receipt from personal items.
A6: Detail of Receipts Submitted for Reimbursement List each receipt and the amount to be reimbursed. Write the receipt number on each receipt.
A7: Rcpt # | B7: Merchant Name | D7: Purpose and Description of Purchase | E7: Enter account descriptions in column headings, and separate amounts by account. Separate tax where necessary.
K8: Total
A9: 1 | K9: =SUM(E9:J9) -> 0
A10: 2 | K10: =SUM(E10:J10) -> 0
A11: 3 | K11: =SUM(E11:J11) -> 0
A12: 4 | K12: =SUM(E12:J12) -> 0
A13: 5 | K13: =SUM(E13:J13) -> 0
A14: 6 | K14: =SUM(E14:J14) -> 0
A15: 7 | K15: =SUM(E15:J15) -> 0
A16: 8 | K16: =SUM(E16:J16) -> 0
A17: 9 | K17: =SUM(E17:J17) -> 0
A18: 10 | K18: =SUM(E18:J18) -> 0
A19: 11 | K19: =SUM(E19:J19) -> 0
A20: 12 | K20: =SUM(E20:J20) -> 0
... A38: 30 | K38: =SUM(E38:J38) -> 0
A39: Account totals | E39: =SUM(E9:E38) -> 0 | F39: =SUM(F9:F38) -> 0 | G39: =SUM(G9:G38) -> 0 | H39: =SUM(H9:H38) -> 0 | I39: =SUM(I9:I38) -> 0 | J39: =SUM(J9:J38) -> 0 | K39: =SUM(E39:J39) -> 0

Sheet Lookups
A3: January
A4: February
A5: March
A6: April
A7: May
A8: June
A9: July
A10: August
A11: September
A12: October
A13: November
A14: December

Sheet Additional Varied Travel
A1: Reimbursement rate | C1: ='Reimbursement Request'!T4 -> 0.7
A2: Date | B2: Starting point (specific location) | C2: Destination (specific location) | D2: Purpose | E2: Mi. or km | F2: Fares or tolls | G2: Amount
G3: =ROUND(E3*$C$1+F3,2) -> 0
G4: =ROUND(E4*$C$1+F4,2) -> 0
G5: =ROUND(E5*$C$1+F5,2) -> 0
G6: =ROUND(E6*$C$1+F6,2) -> 0
G7: =ROUND(E7*$C$1+F7,2) -> 0
G8: =ROUND(E8*$C$1+F8,2) -> 0
G9: =ROUND(E9*$C$1+F9,2) -> 0
G10: =ROUND(E10*$C$1+F10,2) -> 0
G11: =ROUND(E11*$C$1+F11,2) -> 0
G12: =ROUND(E12*$C$1+F12,2) -> 0
G13: =ROUND(E13*$C$1+F13,2) -> 0
G14: =ROUND(E14*$C$1+F14,2) -> 0
... G20: =ROUND(E20*$C$1+F20,2) -> 0
E21: =IF(ISNUMBER(C21-B21),C21-B21,0) -> 0 | G21: =ROUND(E21*$C$1+F21,2) -> 0
E22: =IF(ISNUMBER(C22-B22),C22-B22,0) -> 0 | G22: =ROUND(E22*$C$1+F22,2) -> 0
E23: =IF(ISNUMBER(C23-B23),C23-B23,0) -> 0 | G23: =ROUND(E23*$C$1+F23,2) -> 0
E24: =IF(ISNUMBER(C24-B24),C24-B24,0) -> 0 | G24: =ROUND(E24*$C$1+F24,2) -> 0
E25: =IF(ISNUMBER(C25-B25),C25-B25,0) -> 0 | G25: =ROUND(E25*$C$1+F25,2) -> 0
E26: =IF(ISNUMBER(C26-B26),C26-B26,0) -> 0 | G26: =ROUND(E26*$C$1+F26,2) -> 0
E27: =IF(ISNUMBER(C27-B27),C27-B27,0) -> 0 | G27: =ROUND(E27*$C$1+F27,2) -> 0
E28: =IF(ISNUMBER(C28-B28),C28-B28,0) -> 0 | G28: =ROUND(E28*$C$1+F28,2) -> 0
E29: =IF(ISNUMBER(C29-B29),C29-B29,0) -> 0 | G29: =ROUND(E29*$C$1+F29,2) -> 0
E30: =IF(ISNUMBER(C30-B30),C30-B30,0) -> 0 | G30: =ROUND(E30*$C$1+F30,2) -> 0
E31: =IF(ISNUMBER(C31-B31),C31-B31,0) -> 0 | G31: =ROUND(E31*$C$1+F31,2) -> 0
E32: =IF(ISNUMBER(C32-B32),C32-B32,0) -> 0 | G32: =ROUND(E32*$C$1+F32,2) -> 0
... E56: =IF(ISNUMBER(C56-B56),C56-B56,0) -> 0 | G56: =ROUND(E56*$C$1+F56,2) -> 0
E57: =SUM(E3:E56) -> 0 | F57: =SUM(F3:F56) -> 0 | G57: =SUM(G3:G56) -> 0
